<mujoco model="SLIP">
  <compiler inertiafromgeom="true" angle="degree" />
  
  <default>
    <joint limited='true' damping='1' armature='1' />
    <geom contype='7' conaffinity='7' condim='1' rgba='0.8 0.6 .4 1' margin="0.001" solref=".005 1" solimp=".8 .8 .01" material="geom" />
    <motor ctrlrange='-.4 .4' ctrllimited='true' />  
  </default>
  
  <option timestep="0.001" integrator="Euler" gravity="0 0 -9.806"/>
  <asset>
    <texture type="skybox" builtin="gradient" width="100" height="100" rgb1="1 1 1" rgb2="0 0 0" />
    <texture name="texgeom" type="cube" builtin="flat" mark="cross" width="127" height="1278" rgb1="0.8 0.6 0.4" rgb2="0.8 0.6 0.4" markrgb="1 1 1" random="0.01" />
    <texture name="texplane" type="2d" builtin="checker" rgb1="0 0 0" rgb2="0.8 0.8 0.8" width="100" height="100" />
    <material name='MatPlane' texture="texplane" shininess="1" texrepeat="60 60" specular="1"  reflectance="0.5" />
    <material name='geom' texture="texgeom" texuniform="true" />
  </asset>
  <worldbody>
    <light directional="true" cutoff="100" exponent="1" diffuse="1 1 1" specular=".1 .1 .1" pos="0 0 1.3" dir="-0 0 -1.3" />
    <geom name='floor' contype='7' conaffinity='7' material="MatPlane" pos='0 0 0' size='40 40 40' type='plane' rgba='0.8 0.9 0.8 1' condim='3' friction="2.0" />

    <body name="torso" pos="0 0 1.2">
      <joint name='rootx' type='slide' axis='1 0 0' pos='0 0 0' limited='false' range='-0.001 0.001' damping='0' armature='0' stiffness='0' />
      <joint name='rootz' type='slide' axis='0 0 1' pos='0 0 0' limited='false' range='0.749 0.751' damping='0' armature='0' stiffness='0' ref='1.2'/>
      <joint name='rot' type='hinge' axis='0 1 0' pos='0 0 0' limited='false' damping='0' armature='0' stiffness='0' />
            
      <site name="com_accel" type="sphere" pos="0 0 -0.05" size="0.005"/>
      
      <geom name="torso_geom" type="sphere" size="0.15" friction="0.9"/>
      <body name="left_leg" pos="0 0 -0.15">
        <joint name='left_leg_tau' type = 'hinge' axis='0 1 0' pos='0 0 0.15' limited='true' range='-30 30' damping='0' armature='0.0' stiffness='0' />
	  	<joint name='left_leg_motor' type='slide' axis='0 0 1' pos='0 0 0' limited='true' range='-0.4 0.0' damping='0' armature='0.0' stiffness='0'/>
	    <geom name="left_leg_geom"  type="capsule" contype='2' conaffinity='2' fromto="0 0 0 0 0 -0.1" size="0.05" friction="0.9" rgba="0.1 0.7 0.2 1" />
	    <site name="left_accel" type="sphere" pos="0 0 -0.35" size="0.005"/>
	   
	    <body name="left_toe" pos="0 0 -0.3">
	    	<joint name='left_spring' type='slide' axis='0 0 1' pos='0 0 0' limited='true' range='-0.1 0.3' damping='100' armature='0' stiffness='5000'/>
	        <geom name="left_toe_geom"  contype='2' conaffinity='2' type="sphere" size="0.05" friction="0.1" rgba="0.1 0.7 0.2 1"/>
        	<site name="left_contact" type="sphere" pos="0 0 -0.05" size="0.005"/>
        </body>
      </body>
      <body name="right_leg" pos="0 0 -0.15">
        <joint name='right_leg_tau' type = 'hinge' axis='0 1 0' pos='0 0 0.15' limited='true' range='-30 30' damping='0' armature='0.0' stiffness='0' />
	  	<joint name='right_leg_motor' type='slide' axis='0 0 1' pos='0 0 0' limited='true' range='-0.4 0.0' damping='0' armature='0.0' stiffness='0' />
	    <geom name="right_leg_geom"  contype='4' conaffinity='4' type="capsule" fromto="0 0 0 0 0 -0.1" size="0.05" friction="0.9" rgba="0.7 0.2 0.1 1"/>
	    <site name="right_accel" type="sphere" pos="0 0 -0.35" size="0.005"/>
	    <body name="right_toe" pos="0 0 -0.3">
	    	<joint name='right_spring' type='slide' axis='0 0 1' pos='0 0 0' limited='true' range='-0.1 0.3' damping='100' armature='0' stiffness='5000' />
	        <geom name="right_toe_geom"  contype='4' conaffinity='4' type="sphere" size="0.05" friction="0.1" rgba="0.7 0.2 0.1 1"/>
			<site name="right_contact" type="sphere" pos="0 0 -0.05" size="0.005"/>
        </body>
      </body>



    </body>
  </worldbody>
  
  <actuator>
    <motor joint="left_leg_tau" ctrlrange="-200.0 200.0" ctrllimited="true" />
    <motor joint="left_leg_motor" ctrlrange="-400.0 400.0" ctrllimited="true" />
    <motor joint="right_leg_tau" ctrlrange="-200.0 200.0" ctrllimited="true" />
    <motor joint="right_leg_motor" ctrlrange="-400.0 400.0" ctrllimited="true" />
  </actuator>
</mujoco>
